Workbook

Sheet Raw Data
A1: EmployeeID | B1: Age | C1: Gender | D1: MaritalStatus | E1: Department | F1: JobRole | G1: HireDate | H1: YearsAtCompany | I1: MonthlyIncome | J1: DistanceFromHome_km | K1: OverTime | L1: JobSatisfaction_1to4 | M1: WorkLifeBalance_1to4 | N1: PerformanceRating_1to4 | O1: TrainingSessionsLastYear | P1: Attrition
A2: EMP1402 | B2: 20 | C2: Female | D2: Single | E2: Sales | F2: Sales Manager | G2: 2025-11-08 | H2: 0 | I2: 14306 | J2: 10 | K2: No | L2: 3 | M2: 4 | N2: 4 | O2: 3 | P2: No
A3: EMP1284 | B3: 27 | C3: Male | D3: Divorced | E3: Research & Development | F3: R&D Manager | G3: 2020-02-23 | H3: 6 | I3: 12621 | J3: 15 | K3: No | L3: 4 | M3: 4 | N3: 4 | O3: 3 | P3: No
A4: EMP1415 | B4: 41 | C4: Female | D4: Married | E4: Research & Development | F4: Laboratory Technician | G4: 2025-09-28 | H4: 0 | I4: 3321 | J4: 1 | K4: Yes | L4: 4 | M4: 4 | N4: 3 | O4: 1 | P4: No
A5: EMP1483 | B5: 35 | C5: Female | D5: Married | E5: Research & Development | F5: R&D Manager | G5: 2024-02-29 | H5: 2 | I5: 12188 | J5: 1 | K5: No | L5: 4 | M5: 4 | N5: 4 | O5: 2 | P5: No
A6: EMP1420 | B6: 32 | C6: Female | D6: Married | E6: Sales | F6: Sales Representative | G6: 2022-06-11 | H6: 4 | I6: 3326 | J6: 9 | K6: Yes | L6: 3 | M6: 3 | N6: 3 | O6: 2 | P6: Yes
A7: EMP1169 | B7: 41 | C7: Female | D7: Married | E7: Sales | F7: Sales Executive | G7: 2025-10-10 | H7: 0 | I7: 7359 | J7: 1 | K7: No | L7: 3 | M7: 4 | N7: 3 | O7: 4 | P7: Yes
A8: EMP1246 | B8: 46 | C8: Male | D8: Married | E8: Sales | F8: Sales Manager | G8: 2023-04-21 | H8: 3 | I8: 10993 | J8: 9 | K8: Yes | L8: 4 | M8: 3 | N8: 3 | O8: 4 | P8: No
A9: EMP1553 | B9: 38 | C9: Male | D9: Married | E9: Sales | F9: Sales Executive | G9: 2026-06-27 | H9: 0 | I9: 6979 | J9: 17 | K9: No | L9: 3 | M9: 1 | N9: 3 | O9: 0 | P9: No
A10: EMP1233 | B10: 29 | C10: Male | D10: Married | E10: Research & Development | F10: R&D Manager | G10: 2022-05-01 | H10: 4 | I10: 12571 | J10: 30 | K10: No | L10: 3 | M10: 3 | N10: 4 | O10: 4 | P10: No
A11: EMP1453 | B11: 41 | C11: Female | D11: Married | E11: Research & Development | F11: R&D Manager | G11: 2026-03-25 | H11: 0 | I11: 13374 | J11: 13 | K11: Yes | L11: 2 | M11: 1 | N11: 3 | O11: 3 | P11: Yes
A12: EMP1589 | B12: 22 | C12: Male | D12: Single | E12: Research & Development | F12: R&D Manager | G12: 2018-02-13 | H12: 8 | I12: 14236 | J12: 7 | K12: No | L12: 3 | M12: 1 | N12: 3 | O12: 3 | P12: No
A13: EMP1325 | B13: 48 | C13: Male | D13: Married | E13: Research & Development | F13: Laboratory Technician | G13: 2025-07-04 | H13: 1 | I13: 2620 | J13: 3 | K13: Yes | L13: 3 | M13: 4 | N13: 3 | O13: 5 | P13: No
... A22: EMP1512 | B22: 50 | C22: Female | D22: Married | E22: Research & Development | F22: Research Scientist | G22: 2022-06-06 | H22: 4 | I22: 5929 | J22: 6 | K22: No | L22: 3 | M22: 3 | N22: 3 | O22: 0 | P22: No
A23: EMP1466 | B23: 34 | C23: Male | D23: Single | E23: Research & Development | F23: Manufacturing Engineer | G23: 2022-07-14 | H23: 4 | I23: 5790 | J23: 6 | K23: No | L23: 3 | N23: 4 | O23: 2 | P23: No
A24: EMP1240 | B24: 28 | C24: Female | D24: Single | E24: Research & Development | F24: Research Scientist | G24: 2021-04-14 | H24: 5 | I24: 5839 | J24: 20 | K24: No | L24: 1 | M24: 4 | N24: 3 | O24: 0 | P24: No
A25: EMP1405 | B25: 28 | C25: Female | D25: Single | E25: Research & Development | F25: R&D Manager | G25: 2025-01-03 | H25: 1 | I25: 10600 | J25: 3 | K25: Yes | L25: 3 | M25: 2 | N25: 3 | O25: 1 | P25: Yes
A26: EMP1244 | B26: 37 | C26: Male | D26: Single | E26: Research & Development | F26: R&D Manager | G26: 2017-01-30 | H26: 9 | I26: 10698 | J26: 6 | K26: Yes | L26: 2 | M26: 2 | N26: 3 | O26: 1 | P26: No
A27: EMP1429 | B27: 20 | C27: Female | D27: Single | E27: Sales | F27: Sales Representative | G27: 2018-05-23 | H27: 8 | I27: 3998 | J27: 5 | K27: No | L27: 1 | M27: 2 | N27: 3 | O27: 4 | P27: Yes
A28: EMP1279 | B28: 27 | C28: Female | D28: Single | E28: Sales | F28: Sales Executive | G28: 2025-05-11 | H28: 1 | I28: 6716 | J28: 4 | K28: No | L28: 2 | M28: 4 | N28: 3 | O28: 5 | P28: Yes
A29: EMP1189 | B29: 28 | C29: Female | D29: Single | E29: Research & Development | F29: Laboratory Technician | G29: 2021-06-02 | H29: 5 | I29: 4044 | J29: 6 | K29: No | L29: 3 | M29: 3 | N29: 3 | O29: 4 | P29: No
A30: EMP1133 | B30: 23 | C30: Female | D30: Married | E30: Research & Development | F30: Manufacturing Engineer | G30: 2010-01-08 | H30: 16 | I30: 4802 | J30: 2 | K30: Yes | L30: 1 | M30: 4 | N30: 3 | O30: 0 | P30: No
A31: EMP1295 | B31: 45 | C31: Male | D31: Single | E31: Research & Development | F31: R&D Manager | G31: 2016-12-25 | H31: 9 | I31: 15084 | J31: 1 | K31: No | L31: 1 | M31: 3 | N31: 3 | O31: 5 | P31: No
A32: EMP1515 | B32: 42 | C32: Female | D32: Single | E32: Research & Development | F32: Manufacturing Engineer | G32: 2018-10-16 | H32: 7 | I32: 5856 | J32: 19 | K32: No | L32: 2 | M32: 1 | N32: 3 | O32: 3 | P32: No
A33: EMP1142 | B33: 43 | C33: Female | D33: Divorced | E33: Research & Development | F33: Research Scientist | G33: 2023-09-20 | H33: 2 | I33: 5697 | J33: 6 | K33: Yes | L33: 2 | M33: 3 | N33: 4 | O33: 0 | P33: No
A34: EMP1380 | B34: 20 | C34: Female | D34: Married | E34: Sales | F34: Sales Manager | G34: 2024-04-11 | H34: 2 | I34: 12769 | J34: 9 | K34: No | L34: 4 | M34: 4 | N34: 3 | O34: 3 | P34: No
A35: EMP1550 | B35: 36 | C35: Female | D35: Single | E35: Research & Development | F35: R&D Manager | G35: 2026-07-05 | H35: 0 | I35: 14370 | J35: 3 | K35: No | L35: 1 | M35: 3 | N35: 3 | O35: 4 | P35: Yes
... A42: EMP1500 | B42: 34 | C42: Male | D42: Single | E42: Research & Development | F42: Manufacturing Engineer | G42: 2020-01-24 | H42: 6 | I42: 6281 | J42: 8 | K42: Yes | L42: 4 | M42: 3 | N42: 3 | O42: 4 | P42: No
A43: EMP1547 | B43: 26 | C43: Female | D43: Single | E43: Sales | F43: Sales Manager | G43: 2019-04-28 | H43: 7 | J43: 8 | K43: No | L43: 3 | M43: 1 | N43: 3 | O43: 5 | P43: Yes
A44: EMP1100 | B44: 27 | C44: Male | D44: Divorced | E44: Research & Development | F44: Manufacturing Engineer | G44: 2026-01-21 | H44: 0 | I44: 5920 | J44: 10 | K44: Yes | L44: 4 | M44: 3 | N44: 4 | O44: 5 | P44: Yes
A45: EMP1210 | B45: 46 | C45: Female | D45: Married | E45: Sales | F45: Sales Executive | G45: 2022-05-08 | H45: 4 | I45: 4663 | J45: 10 | K45: Yes | L45: 2 | M45: 3 | N45: 3 | O45: 5 | P45: No
A46: EMP1143 | B46: 45 | C46: Female | D46: Married | E46: Research & Development | F46: Laboratory Technician | G46: 2018-11-18 | H46: 7 | I46: 3647 | J46: 4 | K46: No | L46: 4 | M46: 4 | N46: 4 | O46: 3 | P46: No
A47: EMP1387 | B47: 33 | C47: Female | D47: Married | E47: Sales | F47: Sales Executive | G47: 2025-02-12 | H47: 1 | I47: 4565 | J47: 1 | K47: No | L47: 2 | M47: 2 | N47: 3 | O47: 5 | P47: Yes
A48: EMP1257 | B48: 31 | C48: Male | D48: Married | E48: Research & Development | F48: Laboratory Technician | G48: 2023-04-11 | H48: 3 | I48: 3185 | J48: 4 | K48: No | L48: 2 | M48: 3 | N48: 3 | O48: 0 | P48: No
A49: EMP1584 | B49: 20 | C49: Male | D49: Married | E49: Human Resources | F49: HR Manager | G49: 2024-03-15 | H49: 2 | I49: 12135 | J49: 4 | K49: No | L49: 4 | M49: 2 | N49: 4 | O49: 3 | P49: No
A50: EMP1214 | B50: 50 | C50: Female | D50: Married | E50: Research & Development | F50: Research Scientist | G50: 2020-06-26 | H50: 6 | I50: 6065 | J50: 1 | K50: No | L50: 4 | M50: 4 | N50: 3 | O50: 3 | P50: No
A51: EMP1071 | B51: 35 | C51: Male | D51: Single | E51: Research & Development | F51: Manufacturing Engineer | G51: 2024-11-27 | H51: 1 | I51: 5829 | J51: 3 | K51: No | L51: 2 | M51: 3 | N51: 3 | O51: 0 | P51: Yes
A52: EMP1135 | B52: 44 | C52: Male | D52: Single | E52: Sales | F52: Sales Executive | G52: 2025-11-23 | H52: 0 | I52: 6234 | J52: 15 | K52: Yes | L52: 1 | M52: 4 | N52: 3 | O52: 0 | P52: No
A53: EMP1285 | B53: 47 | C53: Male | D53: Married | E53: Research & Development | F53: Research Scientist | G53: 2021-01-23 | H53: 5 | I53: 6610 | J53: 4 | K53: No | L53: 4 | M53: 4 | N53: 4 | O53: 2 | P53: No
A54: EMP1061 | B54: 40 | C54: Male | D54: Single | E54: Research and Development | F54: Laboratory Technician | G54: 2025-12-13 | H54: 0 | I54: 4029 | J54: 1 | K54: No | L54: 1 | M54: 2 | N54: 3 | O54: 5 | P54: Yes
...

Sheet Cleaned Data
A1: EmployeeID | B1: Age | C1: Gender | D1: MaritalStatus | E1: Department | F1: JobRole | G1: HireDate | H1: YearsAtCompany | I1: TenureBand | J1: MonthlyIncome | K1: DistanceFromHome_km | L1: OverTime | M1: JobSatisfaction_1to4 | N1: WorkLifeBalance_1to4 | O1: PerformanceRating_1to4 | P1: TrainingSessionsLastYear | Q1: Attrition
A2: EMP1001 | B2: 20 | C2: Female | D2: Single | E2: Sales | F2: Sales Manager | G2: 2025-11-08 | H2: 0 | I2: 0-2 | J2: 14306 | K2: 10 | L2: No | M2: 3 | N2: 4 | O2: 4 | P2: 3 | Q2: No
A3: EMP1002 | B3: 27 | C3: Male | D3: Divorced | E3: Research & Development | F3: R&D Manager | G3: 2020-02-23 | H3: 6 | I3: 6-10 | J3: 12621 | K3: 15 | L3: No | M3: 4 | N3: 4 | O3: 4 | P3: 3 | Q3: No
A4: EMP1004 | B4: 41 | C4: Female | D4: Married | E4: Research & Development | F4: Laboratory Technician | G4: 2025-09-28 | H4: 0 | I4: 0-2 | J4: 3321 | K4: 1 | L4: Yes | M4: 4 | N4: 4 | O4: 3 | P4: 1 | Q4: No
A5: EMP1005 | B5: 35 | C5: Female | D5: Married | E5: Research & Development | F5: R&D Manager | G5: 2024-02-29 | H5: 2 | I5: 0-2 | J5: 12188 | K5: 1 | L5: No | M5: 4 | N5: 4 | O5: 4 | P5: 2 | Q5: No
A6: EMP1006 | B6: 32 | C6: Female | D6: Married | E6: Sales | F6: Sales Representative | G6: 2022-06-11 | H6: 4 | I6: 3-5 | J6: 3326 | K6: 9 | L6: Yes | M6: 3 | N6: 3 | O6: 3 | P6: 2 | Q6: Yes
A7: EMP1007 | B7: 41 | C7: Female | D7: Married | E7: Sales | F7: Sales Executive | G7: 2025-10-10 | H7: 0 | I7: 0-2 | J7: 7359 | K7: 1 | L7: No | M7: 3 | N7: 4 | O7: 3 | P7: 4 | Q7: Yes
A8: EMP1009 | B8: 46 | C8: Male | D8: Married | E8: Sales | F8: Sales Manager | G8: 2023-04-21 | H8: 3 | I8: 3-5 | J8: 10993 | K8: 9 | L8: Yes | M8: 4 | N8: 3 | O8: 3 | P8: 4 | Q8: No
A9: EMP1010 | B9: 38 | C9: Male | D9: Married | E9: Sales | F9: Sales Executive | G9: 2026-06-27 | H9: 0 | I9: 0-2 | J9: 6979 | K9: 17 | L9: No | M9: 3 | N9: 1 | O9: 3 | P9: 0 | Q9: No
A10: EMP1011 | B10: 29 | C10: Male | D10: Married | E10: Research & Development | F10: R&D Manager | G10: 2022-05-01 | H10: 4 | I10: 3-5 | J10: 12571 | K10: 30 | L10: No | M10: 3 | N10: 3 | O10: 4 | P10: 4 | Q10: No
A11: EMP1012 | B11: 41 | C11: Female | D11: Married | E11: Research & Development | F11: R&D Manager | G11: 2026-03-25 | H11: 0 | I11: 0-2 | J11: 13374 | K11: 13 | L11: Yes | M11: 2 | N11: 1 | O11: 3 | P11: 3 | Q11: Yes
A12: EMP1013 | B12: 22 | C12: Male | D12: Single | E12: Research & Development | F12: R&D Manager | G12: 2018-02-13 | H12: 8 | I12: 6-10 | J12: 14236 | K12: 7 | L12: No | M12: 3 | N12: 1 | O12: 3 | P12: 3 | Q12: No
A13: EMP1014 | B13: 48 | C13: Male | D13: Married | E13: Research & Development | F13: Laboratory Technician | G13: 2025-07-04 | H13: 1 | I13: 0-2 | J13: 2620 | K13: 3 | L13: Yes | M13: 3 | N13: 4 | O13: 3 | P13: 5 | Q13: No
... A562: EMP1600 | B562: 28 | C562: Female | D562: Single | E562: Sales | F562: Sales Executive | G562: 2018-04-09 | H562: 8 | I562: 6-10 | J562: 6988 | K562: 18 | L562: No | M562: 3 | N562: 3 | O562: 3 | P562: 0 | Q562: No

Sheet Attrition Summary
A1: Employee Attrition Analysis — Summary
A2: Overall Attrition Rate | B2: =COUNTIF('Cleaned Data'!$Q$2:$Q$562,"Yes")/COUNTA('Cleaned Data'!$Q$2:$Q$562) -> 0.27629234
A4: Department | B4: Stayed (No) | C4: Left (Yes) | D4: Total | E4: Attrition Rate
A5: Human Resources | B5: =COUNTIFS('Cleaned Data'!$E$2:$E$562,$A5,'Cleaned Data'!$Q$2:$Q$562,"No") -> 35 | C5: =COUNTIFS('Cleaned Data'!$E$2:$E$562,$A5,'Cleaned Data'!$Q$2:$Q$562,"Yes") -> 11 | D5: =B5+C5 -> 46 | E5: =IF(D5=0,0,C5/D5) -> 0.23913043
A6: Research & Development | B6: =COUNTIFS('Cleaned Data'!$E$2:$E$562,$A6,'Cleaned Data'!$Q$2:$Q$562,"No") -> 236 | C6: =COUNTIFS('Cleaned Data'!$E$2:$E$562,$A6,'Cleaned Data'!$Q$2:$Q$562,"Yes") -> 75 | D6: =B6+C6 -> 311 | E6: =IF(D6=0,0,C6/D6) -> 0.24115756
A7: Sales | B7: =COUNTIFS('Cleaned Data'!$E$2:$E$562,$A7,'Cleaned Data'!$Q$2:$Q$562,"No") -> 135 | C7: =COUNTIFS('Cleaned Data'!$E$2:$E$562,$A7,'Cleaned Data'!$Q$2:$Q$562,"Yes") -> 69 | D7: =B7+C7 -> 204 | E7: =IF(D7=0,0,C7/D7) -> 0.33823529
A10: OverTime | B10: Stayed (No) | C10: Left (Yes) | D10: Total | E10: Attrition Rate
A11: Yes | B11: =COUNTIFS('Cleaned Data'!$L$2:$L$562,$A11,'Cleaned Data'!$Q$2:$Q$562,"No") -> 100 | C11: =COUNTIFS('Cleaned Data'!$L$2:$L$562,$A11,'Cleaned Data'!$Q$2:$Q$562,"Yes") -> 79 | D11: =B11+C11 -> 179 | E11: =IF(D11=0,0,C11/D11) -> 0.44134078
A12: No | B12: =COUNTIFS('Cleaned Data'!$L$2:$L$562,$A12,'Cleaned Data'!$Q$2:$Q$562,"No") -> 306 | C12: =COUNTIFS('Cleaned Data'!$L$2:$L$562,$A12,'Cleaned Data'!$Q$2:$Q$562,"Yes") -> 76 | D12: =B12+C12 -> 382 | E12: =IF(D12=0,0,C12/D12) -> 0.19895288
A15: Job Satisfaction | B15: Stayed (No) | C15: Left (Yes) | D15: Total | E15: Attrition Rate
A16: 1 | B16: =COUNTIFS('Cleaned Data'!$M$2:$M$562,$A16,'Cleaned Data'!$Q$2:$Q$562,"No") -> 46 | C16: =COUNTIFS('Cleaned Data'!$M$2:$M$562,$A16,'Cleaned Data'!$Q$2:$Q$562,"Yes") -> 33 | D16: =B16+C16 -> 79 | E16: =IF(D16=0,0,C16/D16) -> 0.41772152
A17: 2 | B17: =COUNTIFS('Cleaned Data'!$M$2:$M$562,$A17,'Cleaned Data'!$Q$2:$Q$562,"No") -> 87 | C17: =COUNTIFS('Cleaned Data'!$M$2:$M$562,$A17,'Cleaned Data'!$Q$2:$Q$562,"Yes") -> 49 | D17: =B17+C17 -> 136 | E17: =IF(D17=0,0,C17/D17) -> 0.36029412
A18: 3 | B18: =COUNTIFS('Cleaned Data'!$M$2:$M$562,$A18,'Cleaned Data'!$Q$2:$Q$562,"No") -> 128 | C18: =COUNTIFS('Cleaned Data'!$M$2:$M$562,$A18,'Cleaned Data'!$Q$2:$Q$562,"Yes") -> 29 | D18: =B18+C18 -> 157 | E18: =IF(D18=0,0,C18/D18) -> 0.18471338
A19: 4 | B19: =COUNTIFS('Cleaned Data'!$M$2:$M$562,$A19,'Cleaned Data'!$Q$2:$Q$562,"No") -> 145 | C19: =COUNTIFS('Cleaned Data'!$M$2:$M$562,$A19,'Cleaned Data'!$Q$2:$Q$562,"Yes") -> 44 | D19: =B19+C19 -> 189 | E19: =IF(D19=0,0,C19/D19) -> 0.23280423
A22: Tenure Band (yrs) | B22: Stayed (No) | C22: Left (Yes) | D22: Total | E22: Attrition Rate
A23: 0-2 | B23: =COUNTIFS('Cleaned Data'!$I$2:$I$562,$A23,'Cleaned Data'!$Q$2:$Q$562,"No") -> 211 | C23: =COUNTIFS('Cleaned Data'!$I$2:$I$562,$A23,'Cleaned Data'!$Q$2:$Q$562,"Yes") -> 95 | D23: =B23+C23 -> 306 | E23: =IF(D23=0,0,C23/D23) -> 0.31045752
A24: 3-5 | B24: =COUNTIFS('Cleaned Data'!$I$2:$I$562,$A24,'Cleaned Data'!$Q$2:$Q$562,"No") -> 97 | C24: =COUNTIFS('Cleaned Data'!$I$2:$I$562,$A24,'Cleaned Data'!$Q$2:$Q$562,"Yes") -> 37 | D24: =B24+C24 -> 134 | E24: =IF(D24=0,0,C24/D24) -> 0.2761194
A25: 6-10 | B25: =COUNTIFS('Cleaned Data'!$I$2:$I$562,$A25,'Cleaned Data'!$Q$2:$Q$562,"No") -> 79 | C25: =COUNTIFS('Cleaned Data'!$I$2:$I$562,$A25,'Cleaned Data'!$Q$2:$Q$562,"Yes") -> 18 | D25: =B25+C25 -> 97 | E25: =IF(D25=0,0,C25/D25) -> 0.18556701
A26: 10+ | B26: =COUNTIFS('Cleaned Data'!$I$2:$I$562,$A26,'Cleaned Data'!$Q$2:$Q$562,"No") -> 19 | C26: =COUNTIFS('Cleaned Data'!$I$2:$I$562,$A26,'Cleaned Data'!$Q$2:$Q$562,"Yes") -> 5 | D26: =B26+C26 -> 24 | E26: =IF(D26=0,0,C26/D26) -> 0.20833333

Sheet Findings & Recommendations
A1: Employee Attrition Analysis — Findings & Recommendations
A3: Business Problem
A4: HR leadership noticed turnover creeping up but didn't know which employees were most at risk of leaving or why. This analysis works through 600 cleaned employee records to identify the real drivers of attrition.
A6: Method
A7: Cleaned a raw HR dataset (standardized inconsistent department names, removed duplicate records, handled missing values, corrected invalid hire dates). Calculated attrition rate - Left ÷ (Left + Stayed) - segmented by Department, Overtime status, Job Satisfaction, and Tenure using COUNTIFS formulas.
A9: Key Findings
A10: 1. Overtime is the single biggest driver of attrition-employees working overtime leave at more than double the rate of those who don't.
A11: 2. Low job satisfaction nearly doubles attrition risk compared to moderately satisfied employees.
A12: 3. Sales has a noticeably higher attrition rate than Human Resources or Research & Development.
A13: 4. New employees (0-2 years tenure) leave at a substantially higher rate than employees with 10+ years at the company.
A15: Recommendations
A16: 1. Audit overtime distribution, starting with Sales, and address workload imbalances driving burnout.
... A18: 3. Build a structured onboarding and check-in process for employees in their first 2 years, since this is the highest-risk tenure window.
